(venv) PS C:\Users\Alfred John\Fitness_bab-main\wellness-coach-ai\backend> python app.py
Traceback (most recent call last):
  File "C:\Users\Alfred John\Fitness_bab-main\wellness-coach-ai\backend\venv\Lib\site-packages\mysql\connector\connection_cext.py", line 772, in cmd_query
    self._cmysql.query(
_mysql_connector.MySQLInterfaceError: Unknown column 'user.created_at' in 'field list'

The above exception was the direct cause of the following exception:

Traceback (most recent call last):
  File "C:\Users\Alfred John\Fitness_bab-main\wellness-coach-ai\backend\venv\Lib\site-packages\sqlalchemy\engine\base.py", line 1963, in _exec_single_context
    self.dialect.do_execute(
  File "C:\Users\Alfred John\Fitness_bab-main\wellness-coach-ai\backend\venv\Lib\site-packages\sqlalchemy\engine\default.py", line 943, in do_execute
    cursor.execute(statement, parameters)
  File "C:\Users\Alfred John\Fitness_bab-main\wellness-coach-ai\backend\venv\Lib\site-packages\mysql\connector\cursor_cext.py", line 356, in execute
    self._connection.cmd_query(
  File "C:\Users\Alfred John\Fitness_bab-main\wellness-coach-ai\backend\venv\Lib\site-packages\mysql\connector\opentelemetry\context_propagation.py", line 97, in wrapper
    return method(cnx, *args, **kwargs)
           ^^^^^^^^^^^^^^^^^^^^^^^^^^^^
  File "C:\Users\Alfred John\Fitness_bab-main\wellness-coach-ai\backend\venv\Lib\site-packages\mysql\connector\connection_cext.py", line 781, in cmd_query
    raise get_mysql_exception(
mysql.connector.errors.ProgrammingError: 1054 (42S22): Unknown column 'user.created_at' in 'field list'

The above exception was the direct cause of the following exception:

Traceback (most recent call last):
  File "C:\Users\Alfred John\Fitness_bab-main\wellness-coach-ai\backend\app.py", line 179, in <module>
    existing_user = User.query.filter_by(username=default_username).first()
                    ^^^^^^^^^^^^^^^^^^^^^^^^^^^^^^^^^^^^^^^^^^^^^^^^^^^^^^^
  File "C:\Users\Alfred John\Fitness_bab-main\wellness-coach-ai\backend\venv\Lib\site-packages\sqlalchemy\orm\query.py", line 2759, in first
    return self.limit(1)._iter().first()  # type: ignore
           ^^^^^^^^^^^^^^^^^^^^^
  File "C:\Users\Alfred John\Fitness_bab-main\wellness-coach-ai\backend\venv\Lib\site-packages\sqlalchemy\orm\query.py", line 2857, in _iter
    result: Union[ScalarResult[_T], Result[_T]] = self.session.execute(
                                                  ^^^^^^^^^^^^^^^^^^^^^
  File "C:\Users\Alfred John\Fitness_bab-main\wellness-coach-ai\backend\venv\Lib\site-packages\sqlalchemy\orm\session.py", line 2365, in execute
    return self._execute_internal(
           ^^^^^^^^^^^^^^^^^^^^^^^
  File "C:\Users\Alfred John\Fitness_bab-main\wellness-coach-ai\backend\venv\Lib\site-packages\sqlalchemy\orm\session.py", line 2251, in _execute_internal
    result: Result[Any] = compile_state_cls.orm_execute_statement(
                          ^^^^^^^^^^^^^^^^^^^^^^^^^^^^^^^^^^^^^^^^
  File "C:\Users\Alfred John\Fitness_bab-main\wellness-coach-ai\backend\venv\Lib\site-packages\sqlalchemy\orm\context.py", line 306, in orm_execute_statement
    result = conn.execute(
             ^^^^^^^^^^^^^
  File "C:\Users\Alfred John\Fitness_bab-main\wellness-coach-ai\backend\venv\Lib\site-packages\sqlalchemy\engine\base.py", line 1415, in execute
    return meth(
           ^^^^^
  File "C:\Users\Alfred John\Fitness_bab-main\wellness-coach-ai\backend\venv\Lib\site-packages\sqlalchemy\sql\elements.py", line 523, in _execute_on_connection
    return connection._execute_clauseelement(
           ^^^^^^^^^^^^^^^^^^^^^^^^^^^^^^^^^^
  File "C:\Users\Alfred John\Fitness_bab-main\wellness-coach-ai\backend\venv\Lib\site-packages\sqlalchemy\engine\base.py", line 1637, in _execute_clauseelement
    ret = self._execute_context(
          ^^^^^^^^^^^^^^^^^^^^^^
  File "C:\Users\Alfred John\Fitness_bab-main\wellness-coach-ai\backend\venv\Lib\site-packages\sqlalchemy\engine\base.py", line 1842, in _execute_context
    return self._exec_single_context(
           ^^^^^^^^^^^^^^^^^^^^^^^^^^
  File "C:\Users\Alfred John\Fitness_bab-main\wellness-coach-ai\backend\venv\Lib\site-packages\sqlalchemy\engine\base.py", line 1982, in _exec_single_context
    self._handle_dbapi_exception(
  File "C:\Users\Alfred John\Fitness_bab-main\wellness-coach-ai\backend\venv\Lib\site-packages\sqlalchemy\engine\base.py", line 2351, in _handle_dbapi_exception
    raise sqlalchemy_exception.with_traceback(exc_info[2]) from e
  File "C:\Users\Alfred John\Fitness_bab-main\wellness-coach-ai\backend\venv\Lib\site-packages\sqlalchemy\engine\base.py", line 1963, in _exec_single_context
    self.dialect.do_execute(
  File "C:\Users\Alfred John\Fitness_bab-main\wellness-coach-ai\backend\venv\Lib\site-packages\sqlalchemy\engine\default.py", line 943, in do_execute
    cursor.execute(statement, parameters)
  File "C:\Users\Alfred John\Fitness_bab-main\wellness-coach-ai\backend\venv\Lib\site-packages\mysql\connector\cursor_cext.py", line 356, in execute
    self._connection.cmd_query(
  File "C:\Users\Alfred John\Fitness_bab-main\wellness-coach-ai\backend\venv\Lib\site-packages\mysql\connector\opentelemetry\context_propagation.py", line 97, in wrapper
    return method(cnx, *args, **kwargs)
           ^^^^^^^^^^^^^^^^^^^^^^^^^^^^
  File "C:\Users\Alfred John\Fitness_bab-main\wellness-coach-ai\backend\venv\Lib\site-packages\mysql\connector\connection_cext.py", line 781, in cmd_query
    raise get_mysql_exception(
sqlalchemy.exc.ProgrammingError: (mysql.connector.errors.ProgrammingError) 1054 (42S22): Unknown column 'user.created_at' in 'field list'  
[SQL: SELECT user.id AS user_id, user.username AS user_username, user.password AS user_password, user.created_at AS user_created_at        
FROM user
WHERE user.username = %(username_1)s
 LIMIT %(param_1)s]
[parameters: {'username_1': 'testuser', 'param_1': 1}]
(Background on this error at: https://sqlalche.me/e/20/f405)